<?xml version="1.0" encoding="utf-8"?>
<!-- This URDF was automatically created by SolidWorks to URDF Exporter! Originally created by Stephen Brawner (brawner@gmail.com) 
     Commit Version: 1.6.0-1-g15f4949  Build Version: 1.6.7594.29634
     For more information, please see http://wiki.ros.org/sw_urdf_exporter -->
<robot
  name="rosrobot_bilibili">
  <link
    name="base_link">
    <inertial>
      <origin
        xyz="0.000404559499100898 -6.93889390390723E-18 -0.0400231437836262"
        rpy="0 0 0" />
      <mass
        value="4.8879427280419" />
      <inertia
        ixx="0.0194334376308208"
        ixy="1.15866439034747E-19"
        ixz="-9.89189490756364E-05"
        iyy="0.039465636314607"
        iyz="8.07408940376757E-19"
        izz="0.0536001547015263" />
    </inertial>
    <visual>
      <origin
        xyz="0 0 0"
        rpy="0 0 0" />
      <geometry>
        <mesh
          filename="package://rosrobot_bilibili/meshes/base_link.STL" />
      </geometry>
      <material
        name="">
        <color
          rgba="0.792156862745098 0.819607843137255 0.933333333333333 1" />
      </material>
    </visual>
    <collision>
      <origin
        xyz="0 0 0"
        rpy="0 0 0" />
      <geometry>
        <mesh
          filename="package://rosrobot_bilibili/meshes/base_link.STL" />
      </geometry>
    </collision>
  </link>
  <link
    name="lf_link">
    <inertial>
      <origin
        xyz="3.66600088618635E-06 -7.90696511880629E-06 -3.08609181109282E-06"
        rpy="0 0 0" />
      <mass
        value="0.191673894724463" />
      <inertia
        ixx="0.000136743453502309"
        ixy="1.10083989076847E-08"
        ixz="-1.23805208827599E-09"
        iyy="0.000228149012450796"
        iyz="-1.46355873836897E-09"
        izz="0.000136740356752857" />
    </inertial>
    <visual>
      <origin
        xyz="0 0 0"
        rpy="0 0 0" />
      <geometry>
        <mesh
          filename="package://rosrobot_bilibili/meshes/lf_link.STL" />
      </geometry>
      <material
        name="">
        <color
          rgba="0.792156862745098 0.819607843137255 0.933333333333333 1" />
      </material>
    </visual>
    <collision>
      <origin
        xyz="0 0 0"
        rpy="0 0 0" />
      <geometry>
        <mesh
          filename="package://rosrobot_bilibili/meshes/lf_link.STL" />
      </geometry>
    </collision>
  </link>
  <joint
    name="lf_joint"
    type="continuous">
    <origin
      xyz="0.1 0.132 -0.06"
      rpy="0 0 0" />
    <parent
      link="base_link" />
    <child
      link="lf_link" />
    <axis
      xyz="0 -1 0" />
  </joint>
  <link
    name="lb_link">
    <inertial>
      <origin
        xyz="-1.39516264618944E-06 -7.92708113432627E-06 4.55546081804675E-06"
        rpy="0 0 0" />
      <mass
        value="0.191673963011101" />
      <inertia
        ixx="0.000136741383514031"
        ixy="-8.59415545535199E-09"
        ixz="-1.84197968164498E-09"
        iyy="0.000228149138254218"
        iyz="7.22000504543706E-09"
        izz="0.000136742629834816" />
    </inertial>
    <visual>
      <origin
        xyz="0 0 0"
        rpy="0 0 0" />
      <geometry>
        <mesh
          filename="package://rosrobot_bilibili/meshes/lb_link.STL" />
      </geometry>
      <material
        name="">
        <color
          rgba="0.792156862745098 0.819607843137255 0.933333333333333 1" />
      </material>
    </visual>
    <collision>
      <origin
        xyz="0 0 0"
        rpy="0 0 0" />
      <geometry>
        <mesh
          filename="package://rosrobot_bilibili/meshes/lb_link.STL" />
      </geometry>
    </collision>
  </link>
  <joint
    name="lb_joint"
    type="continuous">
    <origin
      xyz="-0.1 0.132 -0.06"
      rpy="0 0 0" />
    <parent
      link="base_link" />
    <child
      link="lb_link" />
    <axis
      xyz="0 -1 0" />
  </joint>
  <link
    name="rf_link">
    <inertial>
      <origin
        xyz="-3.3846E-06 7.9073E-06 -3.386E-06"
        rpy="0 0 0" />
      <mass
        value="0.19167" />
      <inertia
        ixx="0.00013674"
        ixy="1.0643E-08"
        ixz="1.612E-09"
        iyy="0.00022815"
        iyz="2.3614E-09"
        izz="0.00013674" />
    </inertial>
    <visual>
      <origin
        xyz="0 0 0"
        rpy="0 0 0" />
      <geometry>
        <mesh
          filename="package://rosrobot_bilibili/meshes/rf_link.STL" />
      </geometry>
      <material
        name="">
        <color
          rgba="0.79216 0.81961 0.93333 1" />
      </material>
    </visual>
    <collision>
      <origin
        xyz="0 0 0"
        rpy="0 0 0" />
      <geometry>
        <mesh
          filename="package://rosrobot_bilibili/meshes/rf_link.STL" />
      </geometry>
    </collision>
  </link>
  <joint
    name="rf_joint"
    type="continuous">
    <origin
      xyz="0.1 -0.132 -0.06"
      rpy="0 0 0" />
    <parent
      link="base_link" />
    <child
      link="rf_link" />
    <axis
      xyz="0 -1 0" />
  </joint>
  <link
    name="rb_link">
    <inertial>
      <origin
        xyz="-1.39515930830392E-06 7.92708379149243E-06 -4.55546353856154E-06"
        rpy="0 0 0" />
      <mass
        value="0.191673963001509" />
      <inertia
        ixx="0.000136741383513276"
        ixy="8.59417853689208E-09"
        ixz="1.84197884383935E-09"
        iyy="0.000228149138233718"
        iyz="7.21998993944278E-09"
        izz="0.000136742629808743" />
    </inertial>
    <visual>
      <origin
        xyz="0 0 0"
        rpy="0 0 0" />
      <geometry>
        <mesh
          filename="package://rosrobot_bilibili/meshes/rb_link.STL" />
      </geometry>
      <material
        name="">
        <color
          rgba="0.792156862745098 0.819607843137255 0.933333333333333 1" />
      </material>
    </visual>
    <collision>
      <origin
        xyz="0 0 0"
        rpy="0 0 0" />
      <geometry>
        <mesh
          filename="package://rosrobot_bilibili/meshes/rb_link.STL" />
      </geometry>
    </collision>
  </link>
  <joint
    name="rb_joint"
    type="continuous">
    <origin
      xyz="-0.1 -0.132 -0.06"
      rpy="0 0 0" />
    <parent
      link="base_link" />
    <child
      link="rb_link" />
    <axis
      xyz="0 -1 0" />
  </joint>
  <link
    name="lidar_link">
    <inertial>
      <origin
        xyz="0 0 0"
        rpy="0 0 0" />
      <mass
        value="0" />
      <inertia
        ixx="0"
        ixy="0"
        ixz="0"
        iyy="0"
        iyz="0"
        izz="0" />
    </inertial>
    <visual>
      <origin
        xyz="0 0 0"
        rpy="0 0 0" />
      <geometry>
        <mesh
          filename="package://rosrobot_bilibili/meshes/lidar_link.STL" />
      </geometry>
      <material
        name="">
        <color
          rgba="1 1 1 1" />
      </material>
    </visual>
    <collision>
      <origin
        xyz="0 0 0"
        rpy="0 0 0" />
      <geometry>
        <mesh
          filename="package://rosrobot_bilibili/meshes/lidar_link.STL" />
      </geometry>
    </collision>
  </link>
  <joint
    name="lidar_joint"
    type="continuous">
    <origin
      xyz="0.084110111850432 0 0.02"
      rpy="0 0 0" />
    <parent
      link="base_link" />
    <child
      link="lidar_link" />
    <axis
      xyz="0 0 1" />
  </joint>
</robot>